Workbook

Sheet 修　理
A1: 御 見 積 書
H3: 令和 8 年 7 月 日
A4: 下記の通りお見積り申し上げます。
A5: 本見積り金額には消費税は含まれておりませんので | H5: 中部システム工業株式会社
A6: ご契約に際しては、消費税を別途計上願います。 | H6: 〒４５４－０９８１
H7: 名古屋市中川区吉津１丁目２１０９番地
E8: 御中 | H8: アクティブ名古屋西アントレ E 号
E9: 様 | H9: ＴＥＬ ０５２－４１４－４５８０
G10: ＦＡＸ ０５２－４１４－４５８１
K11: 法定福利費＝施工費＋諸経費の 14.05％ | O11: A | P11: H | U11: A | V11: M | W11: H | X11: サイシュウテクノ株式会社
A12: 工事名 | K12: SLA30201 | M12: ハンドルボックス | Q12: SLA30003-1 | S12: メインンパイプ | AB12: 入り | AC12: A | AE12: H
A13: 取引条件 | B13: 従来通り | I13: 一栁 | K13: SLA30301-10-SB | M13: ハンドル | Q13: SLA30003-2 | S13: 終端パイプL=830 | X13: TAT３０－４０７ | Z13: 扉＋捨て箱 | AB13: 5850 | AE13: 10000
A14: 有効期間 | B14: ９０日間 | K14: SLA30201-52 | M14: 埋込ジョインター | Q14: SLA50003-2 | S14: 終端パイプ L=1250 | X14: TAT３０－４０７－２ | Z14: 扉のみ | AB14: 3850
A15: 納入場所 | B15: 現場取付渡し | K15: SLA30250-A | M15: ハンドル L＝１００ | Q15: SLA30105 | S15: パイプジョイント | X15: TAT３０－５０７ | Z15: 扉＋捨て箱 | AB15: 8050 | AE15: 13500
A16: 納期 | B16: お打ち合わせ | K16: SLS30201 | M16: ハンドルボックス | Q16: SLA30108 | S16: クランプ A | X16: TAT３０－５０７－２ | Z16: 扉のみ | AB16: 4950
K17: SLA30220-A-200 | M17: ３００本体 | Q17: SLA50108 | S17: クランプ B
A18: 見積金額 | F18: NET | K18: SLA30420-A-100 | M18: ３００フェース | Q18: SLA30108-C | S18: クランプ C
K19: SLA30120-B-100 | M19: ３００Ⅱフェース | Q19: SLA25102-13 | S19: ダブルクランプ
A20: 窓符号 | B20: 名 称 | F20: 数量 | G20: 単位 | H20: 単 価 | I20: 金額 | J20: 備考 | K20: SLA25202-A | M20: コネクターセットA | Q20: SLA55106 | S20: 終端ネジ
K21: SLA25202-C | M21: コネクターセットC | Q21: SLA55202 | S21: ランナー
K22: SLS25202-A | M22: コネクターセット A 耐蝕 | Q22: SLA20150-A | S22: 外倒し用チェーンケース
K23: SLS25202-C | M23: コネクターセット C 耐蝕 | Q23: SLA45050-S | S23: チェーンケース S | X23: サイシュウテクノ株式会社
K24: SLA30102 | M24: チェーンケース S | Q24: SLA45050-W | S24: チェーンケース W | X24: 厚ケ瀬 | Y24: 峯 | Z24: 法兼
K25: SLA30202 | M25: チェーンケース W | Q25: SLA55107 | S25: 特管 ５５０用 | X25: 総亜産業株式会社
K26: SLA30050-A | M26: チェーンケース W | Q26: S L 25202-12T 特注 | S26: 特管 ２５０・３００用 | X26: 林 | Y26: 竹 内
K27: SLA30050-B | M27: チェーンケース S | Q27: SLA 25102-13 | S27: ダブルクランプ | X27: 春日井硝子株式会社
K28: SLS30050-A | M28: チェーンケース W 耐蝕 | Q28: SLA 30120-111 | S28: マグネットキャッチ | Y28: 藤 本
K29: SLS30050-B | M29: チェーンケース S 耐蝕 | Q29: SLA 55105 | S29: 曲げパイプ 鉄 | X29: 株式会社 名西住建
K30: SLA30107-B | M30: 障子金具 首振り | Q30: SLA 30040 | S30: 曲げパイプ アルミ | Y30: 和 田
K31: SLA30107-C | M31: 障子金具 | Q31: SLA 30020-A ６０φ | S31: 転向ユニット A | X31: 株式会社 オーライズ
K32: SLA50301-A | M32: コネクターセット | Q32: SLA 30020-B 標準 | S32: 転向ユニット B | Y32: 愛 葉
K33: SLA50301-B | M33: コネクターセットL＝1300 | Q33: SLA 30020-A ６０φ | S33: 転向ユニット A | X33: 横井硝子店 | AA33: 川 口
K34: SLA55104-A | M34: レール取付BRT | Q34: SLA 60002-V | S34: V型スクリュージャッキ
K35: SLA55104-B | M35: レール取付BRT L型 | Q35: SLA 60002 | S35: スクリュージャッキユニット
K36: SLA5０００２ | M36: ５００用コネクターセット | Q36: KA25－203 | S36: 内倒し本体BRT
K37: SLA30104-10M | M37: メインケーブル | Q37: KA25－406 | S37: 内倒しBRT L＝１６０
K38: SLA30104-16M | M38: メインケーブル | Q38: KA25－001 | S38: 外倒しBRT L型
K39: SLA30104-24M | M39: メインケーブル | Q39: KA25－004 | S39: 外倒しBRT Z型
K40: SLA30104-50M | M40: メインケーブル | Q40: KA３０－１０１１ | S40: ケース取付金具 ６０P
K41: SLS30004-10M | M41: メインケーブルSUS | Q41: KA３０－９０１ | S41: ケース取付金具
...

Sheet 手配書
A2: 拾 出 表 (A） 兼 発 注マスターカード
A5: お得意先 | B5: お得意先コード | C5: 得意先ご担当 | K5: 発 行 日
A6: オイレスE C O | B6: ３１７０３－１ | C6: 箱崎様 | K6: 月 | L6: 日
A7: 営業所名 | B7: 営業所コード | C7: 受注指令番号 | G7: 出荷先コード | K7: 納 期
A8: 名古屋支店営業G | G8: A １ | K8: 月 | L8: 日
A9: 送り先 | B9: 物 件 名 | K9: E R P 品 目 コ ー ド
A10: 中部システム工業
A12: 伝票番号 | B12: 品工コード | C12: 品 名 | J12: 数 量 | K12: 単 価 | L12: 金 額 | N12: 法定福利費＝施工費＋諸経費の 14.05％ | P12: A | Q12: H | V12: A | W12: M | X12: H | Y12: サイシュウテクノ株式会社
B13: =('修 理'!B22:C22)&"" | C13: =('修 理'!D22)&"" | K13: =VLOOKUP(B13,'[1]オイレス価格表24．11'!$A$4:$F$831,3,0) -> #N/A | L13: =J13*K13 -> #N/A | N13: SLA30201 | O13: ハンドルボックス | R13: SLA30003-1 | T13: メインンパイプ | AC13: 入り | AD13: A | AF13: H
B14: =('修 理'!B23:C23)&"" | C14: =('修 理'!D23)&"" | K14: =VLOOKUP(B14,'[1]オイレス価格表24．11'!$A$4:$F$831,3,0) -> #N/A | L14: =J14*K14 -> #N/A | N14: SLA30301-10-SB | O14: ハンドル | R14: SLA30003-2 | T14: 終端パイプL=830 | Y14: TAT３０－４０７ | AA14: 扉＋捨て箱 | AC14: 5850 | AF14: 10000
B15: =('修 理'!B24:C24)&"" | C15: =('修 理'!D24)&"" | K15: =VLOOKUP(B15,'[1]オイレス価格表24．11'!$A$4:$F$831,3,0) -> #N/A | L15: =J15*K15 -> #N/A | N15: SLA30201-52 | O15: 埋込ジョインター | R15: SLA50003-2 | T15: 終端パイプ L=1250 | Y15: TAT３０－４０７－２ | AA15: 扉のみ | AC15: 3850
B16: =('修 理'!B25:C25)&"" | C16: =('修 理'!D25)&"" | K16: =VLOOKUP(B16,'[1]オイレス価格表24．11'!$A$4:$F$831,3,0) -> #N/A | L16: =J16*K16 -> #N/A | N16: SLA30250-A | O16: ハンドル L＝１００ | R16: SLA30105 | T16: パイプジョイント | Y16: TAT３０－５０７ | AA16: 扉＋捨て箱 | AC16: 8050 | AF16: 13500
B17: =('修 理'!B26:C26)&"" | C17: =('修 理'!D26)&"" | K17: =VLOOKUP(B17,'[1]オイレス価格表24．11'!$A$4:$F$831,3,0) -> #N/A | L17: =J17*K17 -> #N/A | N17: SLS30201 | O17: ハンドルボックス | R17: SLA30108 | T17: クランプ A | Y17: TAT３０－５０７－２ | AA17: 扉のみ | AC17: 4950
B18: =('修 理'!B27:C27)&"" | C18: =('修 理'!D27)&"" | K18: =VLOOKUP(B18,'[1]オイレス価格表24．11'!$A$4:$F$831,3,0) -> #N/A | L18: =J18*K18 -> #N/A | N18: SLA30220-A-200 | O18: ３００本体 | R18: SLA50108 | T18: クランプ B
B19: =('修 理'!B28:C28)&"" | C19: =('修 理'!D28)&"" | K19: =VLOOKUP(B19,'[1]オイレス価格表24．11'!$A$4:$F$831,3,0) -> #N/A | L19: =J19*K19 -> #N/A | N19: SLA30420-A-100 | O19: ３００フェース | R19: SLA30108-C | T19: クランプ C
B20: =('修 理'!B29:C29)&"" | C20: =('修 理'!D29)&"" | K20: =VLOOKUP(B20,'[1]オイレス価格表24．11'!$A$4:$F$831,3,0) -> #N/A | L20: =J20*K20 -> #N/A | N20: SLA30120-B-100 | O20: ３００Ⅱフェース | R20: SLA25102-13 | T20: ダブルクランプ
B21: =('修 理'!B30:C30)&"" | C21: =('修 理'!D30)&"" | K21: =VLOOKUP(B21,'[1]オイレス価格表24．11'!$A$4:$F$831,3,0) -> #N/A | L21: =J21*K21 -> #N/A | N21: SLA25202-A | O21: コネクターセットA | R21: SLA55106 | T21: 終端ネジ
B22: =('修 理'!B31:C31)&"" | C22: =('修 理'!D31)&"" | K22: =VLOOKUP(B22,'[1]オイレス価格表24．11'!$A$4:$F$831,3,0) -> #N/A | L22: =J22*K22 -> #N/A | N22: SLA25202-C | O22: コネクターセットC | R22: SLA55202 | T22: ランナー
B23: =('修 理'!B32:C32)&"" | C23: =('修 理'!D32)&"" | K23: =VLOOKUP(B23,'[1]オイレス価格表24．11'!$A$4:$F$831,3,0) -> #N/A | L23: =J23*K23 -> #N/A | N23: SLS25202-A | O23: コネクターセット A 耐蝕 | R23: SLA20150-A | T23: 外倒し用チェーンケース
B24: =('修 理'!B33:C33)&"" | C24: =('修 理'!D33)&"" | K24: =VLOOKUP(B24,'[1]オイレス価格表24．11'!$A$4:$F$831,3,0) -> #N/A | L24: =J24*K24 -> #N/A | N24: SLS25202-C | O24: コネクターセット C 耐蝕 | R24: SLA45050-S | T24: チェーンケース S | Y24: サイシュウテクノ株式会社
B25: =('修 理'!B34:C34)&"" | C25: =('修 理'!D34)&"" | K25: =VLOOKUP(B25,'[1]オイレス価格表24．11'!$A$4:$F$831,3,0) -> #N/A | L25: =J25*K25 -> #N/A | N25: SLA30102 | O25: チェーンケース S | R25: SLA45050-W | T25: チェーンケース W | Y25: 厚ケ瀬 | Z25: 峯 | AA25: 法兼
B26: =('修 理'!B35:C35)&"" | C26: =('修 理'!D35)&"" | K26: =VLOOKUP(B26,'[1]オイレス価格表24．11'!$A$4:$F$831,3,0) -> #N/A | L26: =J26*K26 -> #N/A | N26: SLA30202 | O26: チェーンケース W | R26: SLA55107 | T26: 特管 ５５０用 | Y26: 総亜産業株式会社
B27: =('修 理'!B36:C36)&"" | C27: =('修 理'!D36)&"" | K27: =VLOOKUP(B27,'[1]オイレス価格表24．11'!$A$4:$F$831,3,0) -> #N/A | L27: =J27*K27 -> #N/A | N27: SLA30050-A | O27: チェーンケース W | R27: S L 25202-12T 特注 | T27: 特管 ２５０・３００用 | Y27: 林 | Z27: 竹 内
B28: =('修 理'!B37:C37)&"" | C28: =('修 理'!D37)&"" | K28: =VLOOKUP(B28,'[1]オイレス価格表24．11'!$A$4:$F$831,3,0) -> #N/A | L28: =J28*K28 -> #N/A | N28: SLA30050-B | O28: チェーンケース S | R28: SLA 25102-13 | T28: ダブルクランプ | Y28: 春日井硝子株式会社
B29: =('修 理'!B38:C38)&"" | C29: =('修 理'!D38)&"" | K29: =VLOOKUP(B29,'[1]オイレス価格表24．11'!$A$4:$F$831,3,0) -> #N/A | L29: =J29*K29 -> #N/A | N29: SLS30050-A | O29: チェーンケース W 耐蝕 | R29: SLA 30120-111 | T29: マグネットキャッチ | Z29: 藤 本
B30: =('修 理'!B39:C39)&"" | C30: =('修 理'!D39)&"" | K30: =VLOOKUP(B30,'[1]オイレス価格表24．11'!$A$4:$F$831,3,0) -> #N/A | L30: =J30*K30 -> #N/A | N30: SLS30050-B | O30: チェーンケース S 耐蝕 | R30: SLA 55105 | T30: 曲げパイプ 鉄 | Y30: 株式会社 名西住建
B31: =('修 理'!B40:C40)&"" | C31: =('修 理'!D40)&"" | K31: =VLOOKUP(B31,'[1]オイレス価格表24．11'!$A$4:$F$831,3,0) -> #N/A | L31: =J31*K31 -> #N/A | N31: SLA30107-B | O31: 障子金具 首振り | R31: SLA 30040 | T31: 曲げパイプ アルミ | Z31: 和 田
B32: =('修 理'!B41:C41)&"" | C32: =('修 理'!D41)&"" | K32: =VLOOKUP(B32,'[1]オイレス価格表24．11'!$A$4:$F$831,3,0) -> #N/A | L32: =J32*K32 -> #N/A | N32: SLA30107-C | O32: 障子金具 | R32: SLA 30020-A ６０φ | T32: 転向ユニット A | Y32: 株式会社 オーライズ
J33: 合計 | K33: =SUM(K13:K32) -> #N/A | L33: =SUM(L13:L32) -> #N/A | N33: SLA50301-A | O33: コネクターセット | R33: SLA 30020-B 標準 | T33: 転向ユニット B | Z33: 愛 葉
N34: SLA50301-B | O34: コネクターセットL＝1300 | R34: SLA 30020-A ６０φ | T34: 転向ユニット A | Y34: 横井硝子店 | AB34: 川 口
N35: SLA55104-A | O35: レール取付BRT | R35: SLA 60002-V | T35: V型スクリュージャッキ
A36: 伝票番号 | D36: 発注者 | N36: SLA55104-B | O36: レール取付BRT L型 | R36: SLA 60002 | T36: スクリュージャッキユニット
D37: 一栁 | N37: SLA5０００２ | O37: ５００用コネクターセット | R37: KA25－203 | T37: 内倒し本体BRT
N38: SLA30104-10M | O38: メインケーブル | R38: KA25－406 | T38: 内倒しBRT L＝１６０
N39: SLA30104-16M | O39: メインケーブル | R39: KA25－001 | T39: 外倒しBRT L型
N40: SLA30104-24M | O40: メインケーブル | R40: KA25－004 | T40: 外倒しBRT Z型
A41: 送り先 名古屋市中川区吉津一丁目２１０９番地アクティブ名古屋西アントレE号 | N41: SLA30104-50M | O41: メインケーブル | R41: KA３０－１０１１ | T41: ケース取付金具 ６０P
A42: TEL ０５２－４１４－４５８０ 中部システム工業株式会社 | N42: SLS30004-10M | O42: メインケーブルSUS | R42: KA３０－９０１ | T42: ケース取付金具
N43: SLS30004-24M | O43: メインケーブルSUS | R43: KA３０－３０１ | T43: ケース取付金具 ５４P
N44: SLS30004-50M | O44: メインケーブルSUS | R44: KA３０－００４ | T44: ケース取付金具
...

Sheet 指示書
A2: 工 事 指 示 書 | P2: 今井硝子
A3: 工事番号 | C3: 受注番号 | N3: 発注日 | P3: 全研工業 | R3: 社長 様 | T3: 中島 様 | V3: 横山 様 | X3: 三友工業 | Z3: 白鳥ガラス | AB3: 専務 様
J4: 発行日 | K4: 令和 8 年 月 日 | N4: 納入日 | P4: 伊藤硝子 | R4: 大森 様 | T4: 安井 様 | V4: 織田 様 | X4: 勝美建材 | Z4: 社長 様
N5: 作成者 | R5: 鈴木 様 | T5: 大河原 様 | V5: 松島 様 | X5: 日本メンテナンス | Z5: 三輪 様
A6: 得意先名 | C6: 担当者 | E6: 携帯電話 | H6: 得意先 TEL | J6: 工 事 名 | N6: サッシ納期 | O6: 材料手配日 | P6: ワールド東海岐阜 | R6: 宮田所長 様 | T6: 横山 様 | V6: 佐藤 様 | X6: 外山サービス | Z6: 外山 様
C7: 様 | P7: ヨシカワテックアド | R7: 社長 様 | T7: 吉川 様 | V7: 天花寺 様 | X7: 凖栄工業 | Z7: 黒川 様 | AB7: ０９０－８８６１－４９０１
A8: 元請先 | C8: 担当者 | E8: 携帯電話 | J8: 工 事 先 住 所 | N8: OP工事 | O8: OP完了 | P8: 日東建材工業 | R8: 社長 様 | T8: 安藤 様 | V8: 加藤 様 | X8: S M C リフォーム | Z8: 築樋 様 | AB8: ０９０－９０２１－６９４０
P9: ワールド東海 | R9: 村瀬 様 | T9: 石橋 様 | V9: 服部 様 | X9: 株式会社 マーク | Z9: 社長 様
A10: ゼネコン | C10: 監督名 | E10: 携帯電話 | H10: 現場 TEL | P10: 服部ガラス | R10: 社長 様 | T10: 小野田 様 | V10: 様 | X10: エステック | Z10: 専務 様
N11: 竣工日 | O11: 施工者 | P11: 愛知マドコン | R11: 服部社長 様 | T11: 斎藤 様 | V11: 松田 様 | X11: 久保田 様 | Z11: 様
A12: 機 種 | C12: 開口形式 | E12: 連窓 | F12: 数量 | G12: ボックス | I12: 角度 | J12: 色 | K12: FL＋ | L12: サッシメーカー | M12: シリーズ | P12: 新和建材㈱ | R12: 社長 様 | T12: 水谷 様 | X12: (有)山岸商店 | Z12: 荒木 様
P13: 三和式ベンチレーター | R13: 田中 様 | T13: 森本 様 | V13: 村田 様 | X13: 愛知マドコン豊橋
P14: 日晶グラシス | R14: 原 様 | T14: 山川 様 | V14: 平塚 様 | Z14: 横山 様
A16: [ 修 理 工 事 内 容 ] | L16: 必要部品 | N16: 数量 | O16: 注文数 | P16: SLA ３０２０１ | R16: ハンドルボックス | U16: SLA ３０２２０－Aー２００ | W16: ハンドルボックス本体 | Y16: SLA ３０２０１－５２ | AA16: 埋込ジョインター
J17: =('修 理'!B22)&"" | L17: =('修 理'!D22)&"" | P17: SLA ２５２０２－A | R17: コネクターセット A | U17: SLA ３０４２０－Aー１００ | W17: ３００フェース
J18: =('修 理'!B23)&"" | L18: =('修 理'!D23)&"" | P18: SLA ３０００３－１ | R18: メインパイプ | U18: SLA
J19: =('修 理'!B24)&"" | L19: =('修 理'!D24)&"" | P19: SLA ３０００３－２ | R19: 終端パイプ | U19: SLS ３０００４－１０ | W19: メインケーブル１０M | Y19: SUS
J20: =('修 理'!B25)&"" | L20: =('修 理'!D25)&"" | P20: SLA ３０１０４－２４ | R20: メインケーブル２４M | U20: SLS ３０００４－２４ | W20: メインケーブル２４M | Y20: SUS
J21: =('修 理'!B26)&"" | L21: =('修 理'!D26)&"" | P21: SLA ３０１０５ | R21: パイプジョイント | U21: SLA ３０１０４－１６ | W21: メインケーブル１６M
J22: =('修 理'!B27)&"" | L22: =('修 理'!D27)&"" | P22: SLA ３０１０８ | R22: クランプ | U22: SLA ３０１０４－１０ | W22: メインケーブル１０M
J23: =('修 理'!B28)&"" | L23: =('修 理'!D28)&"" | P23: SLA ５０３０１－A | R23: コネクターセット A | T23: L1000 | U23: SLS ５５２０３－A | W23: 障子金具 A
J24: =('修 理'!B29)&"" | L24: =('修 理'!D29)&"" | P24: SLA ５０３０１－B | R24: コネクターセット B | T24: L1300 | U24: SLA ５５１０６ | W24: 終端ネジ
J25: =('修 理'!B30)&"" | L25: =('修 理'!D30)&"" | P25: SLA ５５１０４－B | R25: コネクター取付金具 B | U25: SLA ３０２２２ | W25: アッシー
J26: =('修 理'!B31)&"" | L26: =('修 理'!D31)&"" | P26: SLA ５０００２ | R26: ５００用コネクターセット | U26: SLA ３０２２２－SUB | W26: サブアッシー
J27: =('修 理'!B32)&"" | L27: =('修 理'!D32)&"" | P27: KA ３０－１０１１ | R27: ケース取付金具 | U27: SLA ３０１２２－２５M | W27: １３Фフレコン
J28: =('修 理'!B33)&"" | L28: =('修 理'!D33)&"" | P28: SLA ３００５０－A | R28: チェーンケース | U28: SLA
A29: 完 了 証 明 書 令和 ５ 年 月 日 | J29: =('修 理'!B34)&"" | L29: =('修 理'!D34)&"" | P29: SLA ３０２０２ | R29: チェーンケース | U29: SLA
A30: 工事内容 | J30: =('修 理'!B35)&"" | L30: =('修 理'!D35)&"" | P30: SLA ３０１０２ | R30: チェーンケース | U30: SLA
J31: =('修 理'!B36)&"" | L31: =('修 理'!D36)&"" | P31: KA ３０－３０１ | R31: ケース取付金具 | U31: KA２５－２０３ | W31: 本体ブラケット
J32: =('修 理'!B37)&"" | L32: =('修 理'!D37)&"" | P32: SLA ３０１０７－B | R32: 障子金具 首振り | U32: KA２５－４０６ | W32: 内倒しブラケット | Y32: L＝１６０
A33: 証 明 者 ㊞ | J33: =('修 理'!B38)&"" | L33: =('修 理'!D38)&"" | P33: SLA ３０１０７－C | R33: 障子金具 | U33: KA２５－００１ | W33: コネクター取付金具 | Y33: Z
J34: =('修 理'!B39)&"" | L34: =('修 理'!D39)&"" | P34: SLA ２０１５０－A | R34: チェーンケース外倒し | U34: KA２５－２０１ | W34: コネクター取付金具 | Y34: L

Sheet 修理１
A1: 御 見 積 書
H3: 令和 8 年 7 月 日
A4: 下記の通りお見積り申し上げます。
A5: 本見積り金額には消費税は含まれておりませんので | H5: 中部システム工業株式会社
A6: ご契約に際しては、消費税を別途計上願います。 | H6: 〒４５４－０９８１
H7: 名古屋市中川区吉津１丁目２１０９番地
E8: 御中 | H8: アクティブ名古屋西アントレ E 号
E9: 様 | H9: ＴＥＬ ０５２－４１４－４５８０
G10: ＦＡＸ ０５２－４１４－４５８１
L11: R5年 4月5日 価格改定 | P11: A | Q11: H | W11: A | X11: B | Y11: H | AD11: A | AE11: B | AF11: H
A12: 工事名 | L12: SLA81511-A | N12: ハンドルボックス80Ⅲ | R12: 台 | S12: K800030-TA-10 | U12: ８０Ⅲ 押し赤釦SET | W12: 200 | X12: 300 | Y12: 300 | Z12: KA０８－００２ R/L | AB12: 外 ステイBRT枠 | AD12: 330 | AF12: 400 | AI12: MTG-70
A13: 取引条件 | B13: 従来通り | I13: 一栁 | L13: SLA81410-A-200 | N13: ハンドル | R13: 本 | S13: SLA 91510-Aー１０４ | U13: ８０Ⅲ 換気ボタン | W13: 300 | X13: 350 | Y13: 400 | Z13: KA０８－５０２ R/L | AB13: 外 ステイBRT障子 | AD13: 300 | AF13: 380
A14: 有効期間 | B14: ９０日間 | L14: SLA81150-A | N14: ハンドルL＝100 | R14: 台 | S14: SLA ８２６２０-A－１１０T | U14: １１０用換気ボタン | W14: 300 | X14: 350 | Y14: 400 | Z14: KA０８－１００９ L | AB14: 内倒しブラケット | AD14: 1900 | AF14: 2300
A15: 納入場所 | B15: 現場取付渡し | L15: SLA81511-A | N15: ８０-３ 耐蝕向上品 | R15: 台 | S15: SLA ８０６２０-B－１２５ | U15: １００・１10用換気ボタン | W15: 300 | X15: 350 | Y15: 400 | Z15: KA０８－５０５ R/L | AB15: 内 ステイBRT枠 | AD15: 300 | AF15: 400
A16: 納期 | B16: お打ち合わせ | L16: SLA82620-A-200 | N16: １１０－３ 本体 | R16: 台 | S16: SLA ８０１２１－１００ | U16: ハンドル軸心 L＝１００ | W16: 1500 | X16: 1800 | Y16: 2000 | Z16: KA０８－１２６ R/L | AB16: 内 ステイBRT障子 | AD16: 800 | AF16: 1000
L17: SLA82620-A-100 | N17: １１０－３フェース | R17: 台 | S17: SLA81150-A | U17: ハンドル L＝１００ | W17: 1700 | X17: 1900 | Y17: 2100 | Z17: KA８８－２２６ R/L | AB17: 突出ガスステイBRT | AD17: 1350 | AF17: 1700 | AI17: ナット付
A18: 見積金額 | F18: NET | L18: SLA80620-A-200 | N18: １００本体 | R18: 台 | S18: SLA ８２１１０－C－４００ | U18: SLE用ハンドル | W18: 2000 | X18: 2200 | Y18: 2500 | Z18: KA８８－０４２ | AB18: スペーサー | AD18: 100 | AF18: 120
L19: SLA82620-B-100 | N19: １１０Ⅳフェース | R19: 台 | S19: SLA ８２０１０－C－２００ | U19: ダンパーリモコン本体 | W19: 45500 | X19: 50000 | Y19: 55200 | Z19: KA０８－３４０１ | AB19: 突出障子滑車BRT | AD19: 260 | AF19: 320
A20: 窓符号 | B20: 名 称 | F20: 数量 | G20: 単位 | H20: 単 価 | I20: 金額 | J20: 備考 | L20: SLA80620-A-100 | N20: １００フェースA | R20: 台 | S20: K830010TS | U20: ボルトナットセット | W20: 180 | X20: 220 | Y20: 250 | Z20: KA０８－３３１３ | AB20: 突出枠滑車BRT | AD20: 210 | AF20: 250
L21: SLA80620-C-100 | N21: １1０ⅡフェースC | R21: 個 | S21: SLS81130-10M | U21: ワイヤーロープ | W21: 1000 | X21: 1300 | Y21: 1500 | Z21: KA０８－３５６１ R/L | AB21: ケ－シングBRT | AD21: 700 | AF21: 850
L22: SLA85403C | N22: 枠滑車 C | R22: 個 | S22: SLS81130-14M | U22: ワイヤーロープ | W22: 1500 | X22: 1700 | Y22: 1800 | Z22: KA０８－４４１ | AB22: 外 ステイBRT枠 | AD22: 200 | AF22: 250 | AI22: PRO-SE
L23: SLB85603C | N23: 枠滑車Cブロンズ | R23: 個 | S23: SLS81130-18M | U23: ワイヤーロープ | W23: 1800 | X23: 2200 | Y23: 2500 | Z23: KA０８－５０５ R/L | AB23: 外 ステイBRT障子 | AD23: 260 | AF23: 330
L24: SLA85403D | N24: 枠滑車 D | R24: 個 | S24: SLS81130-26M | U24: ワイヤーロープ | W24: 2500 | X24: 3000 | Y24: 3500 | Z24: KA０８－１１０９ | AB24: 内倒しブラケット | AD24: 1200 | AF24: 1500
L25: SLB85603D | N25: 枠滑車Dブロンズ | R25: 個 | S25: SLS81130-50M | U25: ワイヤーロープ | W25: 4500 | X25: 5500 | Y25: 6000 | Z25: KA０８－５０５ R/L | AB25: 内 ステイBRT枠 | AD25: 260 | AF25: 330
L26: SLA85304 | N26: 障子滑車 | R26: 本 | S26: SLA80505-MAO | U26: 丸ステイ | W26: 1900 | X26: 2100 | Y26: 2300 | Z26: KA０８－１４１ R/L | AB26: 内 ステイBRT障子 | AD26: 800 | AF26: 1000
L27: SLB85504 | N27: 障子滑車ブロンズ | R27: 本 | S27: SLA80505-MBO | U27: 丸ステイ | W27: 1900 | X27: 2100 | Y27: 2300 | Z27: KA８８－730-SP | AB27: 内 ケ－シングBRT | AI27: ４０ピッチ H１７
L28: SLA86104 | N28: 障子滑車 | R28: 本 | S28: SLA80505-MCO | U28: 丸ステイ | W28: 2000 | X28: 2200 | Y28: 2400 | Z28: KA０８－４２６６ | AB28: 内 ステイBRT枠 | AD28: 400 | AF28: 500
L29: SLB86104 | N29: 障子滑車 | R29: 本 | S29: SLS ８４１４１－１００T | U29: MTG内倒用内抜キャップ | W29: 650 | X29: 700 | Y29: 800 | Z29: KA０８－４１０５ R/L | AB29: 内 ステイBRT障子 | AD29: 550 | AF29: 680
L30: SLA80505-AO | N30: 丸ステイ | R30: 本 | S30: SLA ８４０３６－１００ | U30: MTG外倒用内抜キャップ | W30: 500 | X30: 600 | Y30: 600 | Z30: KA０８－２２０６ | AB30: 突出 障子滑車BRT | AD30: 300 | AF30: 550
L31: SLA80505-BO | N31: 丸ステイ | R31: 本 | S31: SLA ８４０３６－２００ | U31: MTG外倒用内抜キャップ | W31: 500 | X31: 600 | Y31: 600 | Z31: KA０８－３３０４ | AB31: 突出 枠滑車BRT | AD31: 200
L32: SLA80505-CO | N32: 丸ステイ | R32: SET | S32: G S ２８１１９-K１ | U32: ガスステイ １５φ | W32: 2100 | X32: 2400 | Y32: 2600 | Z32: KA０８－２２０７ | AB32: 突出 障子滑車BRT
L33: SLA80505-DO | N33: 丸ステイ | R33: 本 | S33: G S ８０６０５-AO | U33: ガスステイ １５φ | W33: 2500 | X33: 2700 | Y33: 3000 | Z33: KA０８－３５３２ | AB33: ケ－シングBRT | AD33: 700 | AF33: 850
L34: SLA80505-EO | N34: 丸ステイ | R34: 本 | S34: G S ８０６０５-BO | U34: ガスステイ １５φ | W34: 2500 | X34: 2700 | Y34: 3000 | Z34: KA０８－３３１６ | AB34: スペーサー | AD34: 300
L35: SLA80505-FO | N35: 丸ステイ | R35: 本 | S35: G S ８０６０５-CO | U35: ガスステイ １５φ | W35: 2500 | X35: 2800 | Y35: 3000 | Z35: KA８８－２０８ | AD35: 500 | AF35: 600
L36: SLA80309 | N36: ビスセット | R36: 個 | S36: G S ８０６０５-DO | U36: ガスステイ １５φ | W36: 2600 | X36: 2900 | Y36: 3200 | Z36: KA８８－１３００ | AB36: 中間キャップ | AD36: 300 | AF36: 400
L37: SLA82131-10M | N37: コンジット９ | R37: 個 | S37: G S ８０６０５-EO | U37: ガスステイ １５φ | W37: 2700 | X37: 3000 | Y37: 3300 | Z37: KA８８－730 | AB37: ケーシングBRT L型 | AD37: 350 | AF37: 450
L38: SLA82131-25M | N38: コンジット９ | R38: 本 | S38: G S ８０６０５-FO | U38: ガスステイ １５φ | W38: 2800 | X38: 3100 | Y38: 3320 | Z38: KA０８－８０２ R/L | AD38: 600 | AF38: 750
L39: SLA82131-50M | N39: コンジット９ | R39: 個 | S39: G S ３５０２５-K１ | U39: ガスステイ ２２φ | W39: 2800 | X39: 3100 | Y39: 3400 | Z39: SLA ８６１０４ | AB39: 障子滑車 | AE39: 650
L40: SLA82041A | N40: ケーシングキャップ | R40: 台 | S40: G S ５００２７-K１ | U40: ガスステイ ２２φ | W40: 2800 | X40: 3100 | Y40: 3400 | Z40: KA ０８－２２０２ | AB40: 障子滑車取付金具 | AE40: 360
L41: SLA82042 | N41: ９φコンジットクランプ | R41: 本 | S41: G S ２８１２５-１８ | U41: ガスステイ １８φ | W41: 2700 | X41: 3000 | Y41: 3300 | Z41: KA０８－2207 | AB41: スペーサー | AD41: 200 | AE41: 250 | AF41: 300
...

Sheet 手配書1
A2: 拾 出 表 (A） 兼 発 注マスターカード
A5: お得意先 | B5: お得意先コード | C5: 得意先ご担当 | K5: 発 行 日
A6: オイレスE C O | B6: ３１７０３－１ | C6: 箱崎様 | K6: 月 | L6: 日
A7: 営業所名 | B7: 営業所コード | C7: 受注指令番号 | G7: 出荷先コード | K7: 納 期
A8: 名古屋支店営業G | G8: A １ | K8: 月 | L8: 日
A9: 送り先 | B9: 物 件 名 | K9: E R P 品 目 コ ー ド
A10: 中部システム工業
N11: R5年 4月5日 価格改定 | P11: A | Q11: H | W11: A | X11: B | Y11: H | AD11: A | AE11: B | AF11: H
A12: 伝票番号 | B12: 品工コード | C12: 品 名 | J12: 数 量 | K12: 単 価 | L12: 金 額 | N12: SLA81511-A | O12: ハンドルボックス80Ⅲ | R12: 台 | S12: K800030-TA-10 | U12: ８０Ⅲ 押し赤釦SET | W12: 200 | X12: 300 | Y12: 300 | Z12: KA０８－００２ R/L | AB12: 外 ステイBRT枠 | AD12: 330 | AF12: 400
B13: =(修理１!B22)&"" | C13: =(修理１!D22)&"" | K13: =VLOOKUP(B13,'[1]オイレス価格表24．11'!$A$4:$F$831,3,0) -> #N/A | L13: =J13*K13 -> #N/A | N13: SLA81410-A-200 | O13: ハンドル | R13: 本 | S13: SLA 91510-Aー１０４ | U13: ８０Ⅲ 換気ボタン | W13: 300 | X13: 350 | Y13: 400 | Z13: KA０８－５０２ R/L | AB13: 外 ステイBRT障子 | AD13: 300 | AF13: 380
B14: =(修理１!B23)&"" | C14: =(修理１!D23)&"" | K14: =VLOOKUP(B14,'[1]オイレス価格表24．11'!$A$4:$F$831,3,0) -> #N/A | L14: =J14*K14 -> #N/A | N14: SLA81150-A | O14: ハンドルL＝100 | R14: 台 | S14: SLA ８２６２０-A－１１０T | U14: １１０用換気ボタン | W14: 300 | X14: 350 | Y14: 400 | Z14: KA０８－１００９ L | AB14: 内倒しブラケット | AD14: 1900 | AF14: 2300
B15: =(修理１!B24)&"" | C15: =(修理１!D24)&"" | K15: =VLOOKUP(B15,'[1]オイレス価格表24．11'!$A$4:$F$831,3,0) -> #N/A | L15: =J15*K15 -> #N/A | N15: SLA81511-A | O15: ８０-３ 耐蝕向上品 | R15: 台 | S15: SLA ８０６２０-B－１２５ | U15: １００・１10用換気ボタン | W15: 300 | X15: 350 | Y15: 400 | Z15: KA０８－５０５ R/L | AB15: 内 ステイBRT枠 | AD15: 300 | AF15: 400
B16: =(修理１!B25)&"" | C16: =(修理１!D25)&"" | K16: =VLOOKUP(B16,'[1]オイレス価格表24．11'!$A$4:$F$831,3,0) -> #N/A | L16: =J16*K16 -> #N/A | N16: SLA82620-A-200 | O16: １１０－３ 本体 | R16: 台 | S16: SLA ８０１２１－１００ | U16: ハンドル軸心 L＝１００ | W16: 1500 | X16: 1800 | Y16: 2000 | Z16: KA０８－１２６ R/L | AB16: 内 ステイBRT障子 | AD16: 800 | AF16: 1000
B17: =(修理１!B26)&"" | C17: =(修理１!D26)&"" | K17: =VLOOKUP(B17,'[1]オイレス価格表24．11'!$A$4:$F$831,3,0) -> #N/A | L17: =J17*K17 -> #N/A | N17: SLA82620-A-100 | O17: １１０－３フェース | R17: 台 | S17: SLA81150-A | U17: ハンドル L＝１００ | W17: 1700 | X17: 1900 | Y17: 2100 | Z17: KA８８－２２６ R/L | AB17: 突出ガスステイBRT | AD17: 1350 | AF17: 1700
B18: =(修理１!B27)&"" | C18: =(修理１!D27)&"" | K18: =VLOOKUP(B18,'[1]オイレス価格表24．11'!$A$4:$F$831,3,0) -> #N/A | L18: =J18*K18 -> #N/A | N18: SLA80620-A-200 | O18: １００本体 | R18: 台 | S18: SLA ８２１１０－C－４００ | U18: SLE用ハンドル | W18: 2000 | X18: 2200 | Y18: 2500 | Z18: KA８８－０４２ | AB18: スペーサー | AD18: 100 | AF18: 120
B19: =(修理１!B28)&"" | C19: =(修理１!D28)&"" | K19: =VLOOKUP(B19,'[1]オイレス価格表24．11'!$A$4:$F$831,3,0) -> #N/A | L19: =J19*K19 -> #N/A | N19: SLA82620-B-100 | O19: １１０Ⅳフェース | R19: 台 | S19: SLA ８２０１０－C－２００ | U19: ダンパーリモコン本体 | W19: 45500 | X19: 50000 | Y19: 55200 | Z19: KA０８－３４０１ | AB19: 突出障子滑車BRT | AD19: 260 | AF19: 320
B20: =(修理１!B29)&"" | C20: =(修理１!D29)&"" | K20: =VLOOKUP(B20,'[1]オイレス価格表24．11'!$A$4:$F$831,3,0) -> #N/A | L20: =J20*K20 -> #N/A | N20: SLA80620-A-100 | O20: １００フェースA | R20: 台 | S20: K830010TS | U20: ボルトナットセット | W20: 180 | X20: 220 | Y20: 250 | Z20: KA０８－３３１３ | AB20: 突出枠滑車BRT | AD20: 210 | AF20: 250
B21: =(修理１!B30)&"" | C21: =(修理１!D30)&"" | K21: =VLOOKUP(B21,'[1]オイレス価格表24．11'!$A$4:$F$831,3,0) -> #N/A | L21: =J21*K21 -> #N/A | N21: SLA80620-C-100 | O21: １1０ⅡフェースC | R21: 個 | S21: SLS81130-10M | U21: ワイヤーロープ | W21: 1000 | X21: 1300 | Y21: 1500 | Z21: KA０８－３５６１ R/L | AB21: ケ－シングBRT | AD21: 700 | AF21: 850
B22: =(修理１!B31)&"" | C22: =(修理１!D31)&"" | K22: =VLOOKUP(B22,'[1]オイレス価格表24．11'!$A$4:$F$831,3,0) -> #N/A | L22: =J22*K22 -> #N/A | N22: SLA85403C | O22: 枠滑車 C | R22: 個 | S22: SLS81130-14M | U22: ワイヤーロープ | W22: 1500 | X22: 1700 | Y22: 1800 | Z22: KA０８－４４１ | AB22: 外 ステイBRT枠 | AD22: 200 | AF22: 250
B23: =(修理１!B32)&"" | C23: =(修理１!D32)&"" | K23: =VLOOKUP(B23,'[1]オイレス価格表24．11'!$A$4:$F$831,3,0) -> #N/A | L23: =J23*K23 -> #N/A | N23: SLB85603C | O23: 枠滑車Cブロンズ | R23: 個 | S23: SLS81130-18M | U23: ワイヤーロープ | W23: 1800 | X23: 2200 | Y23: 2500 | Z23: KA０８－５０５ R/L | AB23: 外 ステイBRT障子 | AD23: 260 | AF23: 330
B24: =(修理１!B33)&"" | C24: =(修理１!D33)&"" | K24: =VLOOKUP(B24,'[1]オイレス価格表24．11'!$A$4:$F$831,3,0) -> #N/A | L24: =J24*K24 -> #N/A | N24: SLA85403D | O24: 枠滑車 D | R24: 個 | S24: SLS81130-26M | U24: ワイヤーロープ | W24: 2500 | X24: 3000 | Y24: 3500 | Z24: KA０８－１１０９ | AB24: 内倒しブラケット | AD24: 1200 | AF24: 1500
... B26: =(修理１!B35)&"" | C26: =(修理１!D35)&"" | K26: =VLOOKUP(B26,'[1]オイレス価格表24．11'!$A$4:$F$831,3,0) -> #N/A | L26: =J26*K26 -> #N/A | N26: SLA85304 | O26: 障子滑車 | R26: 本 | S26: SLA80505-MAO | U26: 丸ステイ | W26: 1900 | X26: 2100 | Y26: 2300 | Z26: KA０８－１４１ R/L | AB26: 内 ステイBRT障子 | AD26: 800 | AF26: 1000
B27: =(修理１!B36)&"" | C27: =(修理１!D36)&"" | K27: =VLOOKUP(B27,'[1]オイレス価格表24．11'!$A$4:$F$831,3,0) -> #N/A | L27: =J27*K27 -> #N/A | N27: SLB85504 | O27: 障子滑車ブロンズ | R27: 本 | S27: SLA80505-MBO | U27: 丸ステイ | W27: 1900 | X27: 2100 | Y27: 2300 | Z27: KA８８－730-SP | AB27: 内 ケ－シングBRT
B28: =(修理１!B37)&"" | C28: =(修理１!D37)&"" | K28: =VLOOKUP(B28,'[1]オイレス価格表24．11'!$A$4:$F$831,3,0) -> #N/A | L28: =J28*K28 -> #N/A | N28: SLA86104 | O28: 障子滑車 | R28: 本 | S28: SLA80505-MCO | U28: 丸ステイ | W28: 2000 | X28: 2200 | Y28: 2400 | Z28: KA０８－４２６６ | AB28: 内 ステイBRT枠 | AD28: 400 | AF28: 500
B29: =(修理１!B38)&"" | C29: =(修理１!D38)&"" | K29: =VLOOKUP(B29,'[1]オイレス価格表24．11'!$A$4:$F$831,3,0) -> #N/A | L29: =J29*K29 -> #N/A | N29: SLB86104 | O29: 障子滑車 | R29: 本 | S29: SLS ８４１４１－１００T | U29: MTG内倒用内抜キャップ | W29: 650 | X29: 700 | Y29: 800 | Z29: KA０８－４１０５ R/L | AB29: 内 ステイBRT障子 | AD29: 550 | AF29: 680
B30: =(修理１!B39)&"" | C30: =(修理１!D39)&"" | K30: =VLOOKUP(B30,'[1]オイレス価格表24．11'!$A$4:$F$831,3,0) -> #N/A | L30: =J30*K30 -> #N/A | N30: SLA80505-AO | O30: 丸ステイ | R30: 本 | S30: SLA ８４０３６－１００ | U30: MTG外倒用内抜キャップ | W30: 500 | X30: 600 | Y30: 600 | Z30: KA０８－２２０６ | AB30: 突出 障子滑車BRT | AD30: 300 | AF30: 550
B31: =(修理１!B40)&"" | C31: =(修理１!D40)&"" | K31: =VLOOKUP(B31,'[1]オイレス価格表24．11'!$A$4:$F$831,3,0) -> #N/A | L31: =J31*K31 -> #N/A | N31: SLA80505-BO | O31: 丸ステイ | R31: 本 | S31: SLA ８４０３６－２００ | U31: MTG外倒用内抜キャップ | W31: 500 | X31: 600 | Y31: 600 | Z31: KA０８－３３０４ | AB31: 突出 枠滑車BRT | AD31: 200
B32: =(修理１!B41)&"" | C32: =(修理１!D41)&"" | K32: =VLOOKUP(B32,'[1]オイレス価格表24．11'!$A$4:$F$831,3,0) -> #N/A | L32: =J32*K32 -> #N/A | N32: SLA80505-CO | O32: 丸ステイ | R32: SET | S32: G S ２８１１９-K１ | U32: ガスステイ １５φ | W32: 2100 | X32: 2400 | Y32: 2600 | Z32: KA０８－２２０７ | AB32: 突出 障子滑車BRT
J33: 合計 | K33: =SUM(K13:K32) -> #N/A | L33: =SUM(L13:L32) -> #N/A | N33: SLA80505-DO | O33: 丸ステイ | R33: 本 | S33: G S ８０６０５-AO | U33: ガスステイ １５φ | W33: 2500 | X33: 2700 | Y33: 3000 | Z33: KA０８－３５３２ | AB33: ケ－シングBRT | AD33: 700 | AF33: 850
N34: SLA80505-EO | O34: 丸ステイ | R34: 本 | S34: G S ８０６０５-BO | U34: ガスステイ １５φ | W34: 2500 | X34: 2700 | Y34: 3000 | Z34: KA０８－３３１６ | AB34: スペーサー | AD34: 300
N35: SLA80505-FO | O35: 丸ステイ | R35: 本 | S35: G S ８０６０５-CO | U35: ガスステイ １５φ | W35: 2500 | X35: 2800 | Y35: 3000 | Z35: KA８８－２０８ | AD35: 500 | AF35: 600
A36: 伝票番号 | D36: 発注者 | N36: SLA80309 | O36: ビスセット | R36: 個 | S36: G S ８０６０５-DO | U36: ガスステイ １５φ | W36: 2600 | X36: 2900 | Y36: 3200 | Z36: KA８８－１３００ | AB36: 中間キャップ | AD36: 300 | AF36: 400
D37: 一栁 | N37: SLA82131-10M | O37: コンジット９ | R37: 個 | S37: G S ８０６０５-EO | U37: ガスステイ １５φ | W37: 2700 | X37: 3000 | Y37: 3300 | Z37: KA８８－730 | AB37: ケーシングBRT L型 | AD37: 350 | AF37: 450
N38: SLA82131-25M | O38: コンジット９ | R38: 本 | S38: G S ８０６０５-FO | U38: ガスステイ １５φ | W38: 2800 | X38: 3100 | Y38: 3320 | Z38: KA０８－８０２ R/L | AD38: 600 | AF38: 750
N39: SLA82131-50M | O39: コンジット９ | R39: 個 | S39: G S ３５０２５-K１ | U39: ガスステイ ２２φ | W39: 2800 | X39: 3100 | Y39: 3400 | Z39: SLA ８６１０４ | AB39: 障子滑車 | AE39: 650
N40: SLA82041A | O40: ケーシングキャップ | R40: 台 | S40: G S ５００２７-K１ | U40: ガスステイ ２２φ | W40: 2800 | X40: 3100 | Y40: 3400 | Z40: KA ０８－２２０２ | AB40: 障子滑車取付金具 | AE40: 360
A41: 送り先 名古屋市中川区吉津一丁目２１０９番地アクティブ名古屋西アントレE号 | N41: SLA82042 | O41: ９φコンジットクランプ | R41: 本 | S41: G S ２８１２５-１８ | U41: ガスステイ １８φ | W41: 2700 | X41: 3000 | Y41: 3300 | Z41: KA０８－2207 | AB41: スペーサー | AD41: 200 | AE41: 250 | AF41: 300
A42: TEL ０５２－４１４－４５８０ 中部システム工業株式会社 | N42: SLA30003-1 | O42: メインパイプ | R42: 個 | S42: G S ４２５２３-１８ | U42: ガスステイ １８φ | W42: 2700 | X42: 3000 | Y42: 3300 | Z42: G S ３５０２１-１８ | AB42: ガスステイ １８φ | AD42: 2700 | AE42: 3000 | AF42: 3300
N43: SLA30108-C | O43: クランプ C | R43: 個 | S43: SLA ８０１３１－２５M | U43: 1１φコンジット２５M | W43: 9500 | X43: 11000 | Y43: 12000
N44: SL52H01 | O44: ５０用ハンドルボックス | R44: 個 | S44: SLA ８００１０－２ | U44: 1１φケーシングキャップ | W44: 650 | X44: 750 | Y44: 800
...

Sheet 指示書1
A1: 工 事 指 示 書 | T1: 山本耕司 様 | V1: ０８０－３３５８－９６７５
P2: 三協立山 | Q2: MTG－７０R | R2: 日鉄物産システム建築 | T2: 綾部 様 | V2: ０７０－１４２０－９７４５
P3: オルック㈱ | R3: 斉 藤 様 | T3: 中崎 様 | V3: ０８０－２０６４－０５４７
A4: 工事番号 | C4: 受注番号 | N4: 発注日 | P4: LIXIL | Q4: PRO-SE | R4: 社 長 様 | T4: 横山 様 | V4: ０９０－６９０８－１０５７
I5: 発効日： 令和 8 年 月 日 | N5: 納入日 | P5: 全研工業 | R5: 社 長 様 | T5: 清水 様 | V5: ０９０－７１７４－１４３６
N6: 作成者 | P6: 服部ガラス㈱ | R6: 社 長 様 | T6: 戸谷 様 | V6: 日本メンテナンス | X6: 三輪 様
A7: 得意先名 | C7: 担当者 | E7: 携帯電話 | H7: 得意先 TEL | J7: 工 事 名 | N7: サッシ納期 | P7: 伊藤硝子㈱ | R7: 安井 様 | S7: 大森 様 | T7: 大河原 様 | U7: 織田 様 | V7: 山中 様
P8: 日東建材工業 | R8: 安 藤 様 | T8: 社 長 様
A9: 元請先 | C9: 担当者 | E9: 携帯電話 | J9: 工 事 先 住 所 | N9: OP工事 | O9: OP完了 | P9: ワールド岐阜 | R9: 山本 様 | S9: 宮田 様 | T9: 横山 様 | U9: 加藤 様 | V9: 様
P10: ワールド東海 | R10: 村瀬 様 | S10: 石橋 様 | T10: 服部 様
A11: ゼネコン | C11: 監督名 | E11: 携帯電話 | H11: 現場 TEL | P11: 愛知マドコン | R11: 服部社長 様 | T11: 斎藤 様 | U11: 松田 様 | V11: （株）オ－ライズ | X11: 愛葉 様 | Z11: ０８０－３９１３－５６６４
N12: 竣工日 | O12: 施工者 | P12: (有)今井硝子 | R12: 社長 様 | S12: 鈴木 様 | T12: ヨシカワテックアド | V12: （株）前田建商
A13: 機 種 | C13: 開口形式 | E13: 連窓 | F13: 数量 | G13: ボックス | I13: 角度 | J13: 色 | K13: FL＋ | L13: サッシメーカー | M13: シリーズ | P13: 新和建材 | R13: 社長 様 | V13: (有)勝美建材
P14: 三和式ベンチレーター | R14: 水谷 様 | S14: 田中 様 | T14: 森本 様 | U14: 様
A17: [ 修 理 工 事 内 容 ] | L17: 必要部品 | N17: 数量 | O17: 注文数 | P17: SLA ８１５１１-A | R17: ハンドルボックス８０Ⅲ | T17: SLS ８１１３０－１０ | V17: ワイヤーロープ１０M | X17: LXRBFU－０１ | Z17: 内倒し３点滑車セット
J18: =(修理１!B22)&"" | L18: =(修理１!D22)&"" | P18: SLA ８１４１０-A-200 | R18: 逆転防止ハンドル | T18: SLS ８１１３０－１４ | V18: ワイヤーロープ１４M | X18: LXRBFU－０５ | Z18: 内倒しフレコン金具セト
J19: =(修理１!B23)&"" | L19: =(修理１!D23)&"" | P19: SLA ８１１５０-A | R19: ハンドルL＝１００ | T19: SLS ８１１３０－１８ | V19: ワイヤーロープ１８M | X19: LXRBFS－０１ | Z19: 外倒し３点滑車セット
J20: =(修理１!B24)&"" | L20: =(修理１!D24)&"" | P20: SLA ８２６２０-A-200 | R20: １１０Ⅲ本体 | T20: SLS ８１１３０－２６ | V20: ワイヤーロープ２６M | X20: LXRBFS－０５ | Z20: 外倒しフレコン金具セト
J21: =(修理１!B25)&"" | L21: =(修理１!D25)&"" | P21: SLA ８２６２０-A-１00 | R21: １１０Ⅲフェース | T21: SLA ８２１３１－２５ | V21: コンジット９ ２５M | X21: SLA ８００１０－０２ | Z21: １１Φケーシングキャップ
J22: =(修理１!B26)&"" | L22: =(修理１!D26)&"" | P22: SLZ ８２６２０-A-１00 | R22: １１０Ⅲフェース黒 | T22: SLA ８２１３１－１０ | V22: コンジット９ １０M | X22: SLA ８００１０－０３ | Z22: １１Φコンジットクランプ
J23: =(修理１!B27)&"" | L23: =(修理１!D27)&"" | P23: SLA ８０６２０-A-200 | R23: １００本体 | T23: SLA ８２０４２ | V23: コンジットクランプ ９ | X23: SLA
J24: =(修理１!B28)&"" | L24: =(修理１!D28)&"" | P24: SLA ８０６２０-A-１00 | R24: １００フェース A | T24: SLA ８６１０４ | V24: 障子滑車 | X24: SLB ８５６０３－C | Z24: 枠滑車 C ブロンズ
J25: =(修理１!B29)&"" | L25: =(修理１!D29)&"" | P25: SLA ８０６２０-B-１00 | R25: １１０ ４フェース | T25: SLA ８５４０３－C | V25: 枠滑車 C | X25: SLB ８５６０３－D | Z25: 枠滑車 D ブロンズ
J26: =(修理１!B30)&"" | L26: =(修理１!D30)&"" | P26: SLA ８０６２０-C-１00 | R26: １１０Ⅱフェース | T26: SLA ８５４０３－D | V26: 枠滑車 D | X26: SLB ８５５０４ | Z26: 障子滑車 ブロンズ
J27: =(修理１!B31)&"" | L27: =(修理１!D31)&"" | P27: SLA ８２６1０-A-200 | R27: １１０Ⅲ露出本体 | T27: SLA ８５３０４ | V27: 障子滑車 | X27: SLB ８５５０９－G | Z27: 転向滑車 G
J28: =(修理１!B32)&"" | L28: =(修理１!D32)&"" | P28: SLA ８２６1０-C-200 | R28: １１０ⅢS露出本体(煙感） | T28: SLA ８５２０９－G | V28: 転向滑車 G | X28: SLB ８６１０４ | Z28: 障子滑車
J29: =(修理１!B33)&"" | L29: =(修理１!D33)&"" | P29: SLA ８２６２０-C-200 | R29: １１０ⅢS埋込本体(煙感） | T29: SLA ８６１０４ | V29: 障子滑車
J30: =(修理１!B34)&"" | L30: =(修理１!D34)&"" | P30: SLA ８１５２１-D | R30: ８０Ⅵ埋込ボックス | T30: SLA ８６１０４－A | V30: 障子滑車 | X30: SLA
J31: =(修理１!B35)&"" | L31: =(修理１!D35)&"" | P31: SLA ８１５２１-A | R31: ハンドルボックス８０Ⅵ | T31: GS ３５０２１－１８ | V31: ガスステイ | X31: SLA ５０００２－００３ | Z31: ナットスペシャル
J32: =(修理１!B36)&"" | L32: =(修理１!D36)&"" | P32: SLA ８０５０５－A O | R32: 丸ステイ | T32: K ８３００１０-TS | V32: ボルトナットセット | X32: SL ５２H ０１ | Z32: ハンドルボックス５０用
J33: =(修理１!B37)&"" | L33: =(修理１!D37)&"" | P33: SLA ８０５０５－B O | R33: 丸ステイ | T33: K ８００３０-TA | V33: 押し釦SET | X33: SLA ５１H ０９ | Z33: テンションステイ
J34: =(修理１!B38)&"" | L34: =(修理１!D38)&"" | P34: SLA ８０５０５－C O | R34: 丸ステイ | T34: KA８８－１３００ | V34: 中間キャップ. | X34: SLA ５１H １４－A | Z34: 転向滑車 A
J35: =(修理１!B39)&"" | L35: =(修理１!D39)&"" | P35: SLA ８０５０５－F O | R35: 丸ステイ | T35: SLA | V35: ケーシングブラケットL型 | X35: SLA ５１H １４－B | Z35: 転向滑車 B
J36: =(修理１!B40)&"" | L36: =(修理１!D40)&"" | P36: SLA ８０３０９ | R36: ビスセット | T36: GS ６４４５５－K１ | V36: ガスステイ | X36: SLA ５１H ０５ | Z36: ロープ振れ止め金具
J37: =(修理１!B41)&"" | L37: =(修理１!D41)&"" | P37: SLA ８２０４１－A | R37: ケーシングキャップ | T37: GS ８０６０５－DO | V37: ガスステイ | X37: SLA ５１H ０６ | Z37: シンブル
P38: SLA ５０５ R/L | R38: 障子側ステイブラケット | T38: GS ８０６０５－EO | V38: ガスステイ | X38: E/S ０５０－００１ | Z38: ワイヤ－ストッパ－
P39: SLA ４４１ | R39: 枠側ステイブラケット | T39: KA０８－３５３２ | V39: ケーシングブラケット | X39: E/S ０５０－００３ | Z39: 転向滑車 １００
P40: KA８８－７３０ | R40: ケーシングブラケットL型 | T40: KA０８－３５６１－R/L | V40: ケーシングブラケット | X40: E/S ０５０－００４ | Z40: シンブル
P41: SLS ８４１４１－１００T | R41: ケーシングキャップ | T41: KA０８－３３１６ | V41: スぺ－サ－ | X41: E/S ０５０－００５ | Z41: ワイヤ－クリップ
P42: SLA ８３１１０-A R/L | R42: ボールチェーンボックス | Z42: ３Φワイヤーロープ
...

Sheet 新規
A1: 御 見 積 書
H3: 令和 8 年 6 月 日
A4: 下記の通りお見積り申し上げます。
A5: 本見積り金額には消費税は含まれておりませんので | H5: 中部システム工業株式会社
A6: ご契約に際しては、消費税を別途計上願います。 | H6: 〒４５４－０９８１
H7: 名古屋市中川区吉津１丁目２１０９番地
E8: 御中 | H8: アクティブ名古屋西アントレ E 号
E9: 様 | H9: ＴＥＬ ０５２－４１４－４５８０
G10: ＦＡＸ ０５２－４１４－４５８１
L11: R5年 4月5日 価格改定 | P11: A | Q11: H | W11: A | X11: B | Y11: H | AD11: A | AE11: B | AF11: H
A12: 工事名 | L12: SLA ８１５１１－A | N12: ハンドルボックス80Ⅲ | P12: 7500 | Q12: 8500 | R12: 台 | S12: K ８０００３０－TA-１０ | U12: ８０Ⅲ 押し赤釦SET | W12: 200 | X12: 300 | Y12: 300 | Z12: KA０８－００２ R/L | AB12: 外 ステイBRT枠 | AD12: 330 | AF12: 400 | AI12: MTG-70
A13: 取引条件 | B13: 従来通り | I13: 一栁 | L13: SLA ８１４１０-A-200 | N13: ハンドル | P13: 1200 | Q13: 1500 | R13: 本 | S13: SLA 91510-Aー１０４ | U13: ８０Ⅲ 換気ボタン | W13: 300 | X13: 350 | Y13: 400 | Z13: KA０８－５０２ R/L | AB13: 外 ステイBRT障子 | AD13: 300 | AF13: 380
A14: 有効期間 | B14: ９０日間 | L14: SLA ８１１５０－A | N14: ハンドルL＝100 | P14: 2500 | Q14: 3000 | R14: 台 | S14: SLA ８２６２０-A－１１０T | U14: １１０用換気ボタン | W14: 300 | X14: 350 | Y14: 400 | Z14: KA０８－１００９ L | AB14: 内倒しブラケット | AD14: 1900 | AF14: 2300
A15: 納入場所 | B15: 現場取付渡し | L15: SLS ８１５１１-A | N15: ８０-３ 耐蝕向上品 | P15: 11500 | Q15: 12000 | R15: 台 | S15: SLA ８０６２０-B－１２５ | U15: １００・１10用換気ボタン | W15: 300 | X15: 350 | Y15: 400 | Z15: KA０８－５０５ R/L | AB15: 内 ステイBRT枠 | AD15: 300 | AF15: 400
A16: 納期 | B16: お打ち合わせ | L16: SLA 82620-A-200 | N16: １１０－３ 本体 | P16: 13000 | Q16: 14000 | R16: 台 | S16: SLA ８０１２１－１００ | U16: ハンドル軸心 L＝１００ | W16: 1500 | X16: 1800 | Y16: 2000 | Z16: KA０８－１２６ R/L | AB16: 内 ステイBRT障子 | AD16: 800 | AF16: 1000
L17: SLA 82620-A-100 | N17: １１０－３フェース | P17: 9000 | Q17: 10500 | R17: 台 | S17: SLA ８１１５０－A | U17: ハンドル L＝１００ | W17: 1700 | X17: 1900 | Y17: 2100 | Z17: KA８８－２２６ R/L | AB17: 突出ガスステイBRT | AD17: 1350 | AF17: 1700 | AI17: ナット付
A18: 見積金額 | F18: NET | L18: SLA 80620-A-200 | N18: １００本体 | P18: 14000 | Q18: 15000 | R18: 台 | S18: SLA ８２１１０－C－４００ | U18: SLE用ハンドル | W18: 2000 | X18: 2200 | Y18: 2500 | Z18: KA８８－０４２ | AB18: スペーサー | AD18: 100 | AF18: 120
L19: SLA 82620-B-100 | N19: １１０Ⅳフェース | P19: 9500 | Q19: 10500 | R19: 台 | S19: SLA ８２０１０－C－２００ | U19: ダンパーリモコン本体 | W19: 45500 | X19: 50000 | Y19: 55200 | Z19: KA０８－３４０１ | AB19: 突出障子滑車BRT | AD19: 260 | AF19: 320
A20: 窓符号 | B20: 名 称 | F20: 数量 | G20: 単位 | H20: 単 価 | I20: 金額 | J20: 備考 | L20: SLA 80620-A-100 | N20: １００フェースA | P20: 13000 | Q20: 14500 | R20: 台 | S20: K ８３００１０－TS | U20: ボルトナットセット | W20: 180 | X20: 220 | Y20: 250 | Z20: KA０８－３３１３ | AB20: 突出枠滑車BRT | AD20: 210 | AF20: 250
L21: SLA 80620-C-100 | N21: １1０ⅡフェースC | P21: 17000 | Q21: 18000 | R21: 個 | S21: SLS ８１１３０-10M | U21: ワイヤーロープ | W21: 1000 | X21: 1300 | Y21: 1500 | Z21: KA０８－３５６１ R/L | AB21: ケ－シングBRT | AD21: 700 | AF21: 850
L22: SLA ８５４０３C | N22: 枠滑車 C | P22: 700 | Q22: 750 | R22: 個 | S22: SLS ８１１３０-1４M | U22: ワイヤーロープ | W22: 1500 | X22: 1700 | Y22: 1800 | Z22: KA０８－４４１ | AB22: 外 ステイBRT枠 | AD22: 200 | AF22: 250 | AI22: PRO-SE
L23: SLB ８５６０３C | N23: 枠滑車Cブロンズ | P23: 750 | Q23: 800 | R23: 個 | S23: SLS ８１１３０-1８M | U23: ワイヤーロープ | W23: 1800 | X23: 2200 | Y23: 2500 | Z23: KA０８－５０５ R/L | AB23: 外 ステイBRT障子 | AD23: 260 | AF23: 330
L24: SLA ８５４０３D | N24: 枠滑車 D | P24: 700 | Q24: 750 | R24: 個 | S24: SLS ８１１３０-２６M | U24: ワイヤーロープ | W24: 2500 | X24: 3000 | Y24: 3500 | Z24: KA０８－１１０９ | AB24: 内倒しブラケット | AD24: 1200 | AF24: 1500
L25: SLB ８５６０３D | N25: 枠滑車Dブロンズ | P25: 750 | Q25: 800 | R25: 個 | S25: SLS ８１１３０-５0M | U25: ワイヤーロープ | W25: 4500 | X25: 5500 | Y25: 6000 | Z25: KA０８－５０５ R/L | AB25: 内 ステイBRT枠 | AD25: 260 | AF25: 330
L26: SLA ８５３０４ | N26: 障子滑車 | P26: 500 | Q26: 550 | R26: 本 | S26: SLA ８０５０５－MAO | U26: 丸ステイ | W26: 1900 | X26: 2100 | Y26: 2300 | Z26: KA０８－１４１ R/L | AB26: 内 ステイBRT障子 | AD26: 800 | AF26: 1000
L27: SLB ８５５０４ | N27: 障子滑車ブロンズ | P27: 550 | Q27: 600 | R27: 本 | S27: SLA ８０５０５－MBO | U27: 丸ステイ | W27: 1900 | X27: 2100 | Y27: 2300 | Z27: KA８８－730-SP | AB27: 内 ケ－シングBRT | AI27: ４０ピッチ H１７
L28: SLA ８６１０４ | N28: 障子滑車 | P28: 700 | Q28: 750 | R28: 本 | S28: SLA ８０５０５－MCO | U28: 丸ステイ | W28: 2000 | X28: 2200 | Y28: 2400 | Z28: KA０８－４２６６ | AB28: 内 ステイBRT枠 | AD28: 400 | AF28: 500
L29: SLB ８６１０４ | N29: 障子滑車 | P29: 700 | Q29: 750 | R29: 本 | S29: SLS ８４１４１－１００T | U29: MTG内倒用内抜キャップ | W29: 650 | X29: 700 | Y29: 800 | Z29: KA０８－４１０５ R/L | AB29: 内 ステイBRT障子 | AD29: 550 | AF29: 680
L30: SLA 80505－AO | N30: 丸ステイ | P30: 2000 | Q30: 2300 | R30: 本 | S30: SLA ８４０３６－１００ | U30: MTG外倒用内抜キャップ | W30: 500 | X30: 600 | Y30: 600 | Z30: KA０８－２２０６ | AB30: 突出 障子滑車BRT | AD30: 300 | AF30: 550
L31: SLA 80505－BO | N31: 丸ステイ | P31: 2100 | Q31: 2400 | R31: 本 | S31: SLA ８４０３６－２００ | U31: MTG外倒用内抜キャップ | W31: 500 | X31: 600 | Y31: 600 | Z31: KA０８－３３０４ | AB31: 突出 枠滑車BRT | AD31: 200
L32: SLA 80505－CO | N32: 丸ステイ | P32: 2200 | Q32: 2500 | R32: SET | S32: G S ２８１１９-K１ | U32: ガスステイ １５φ | W32: 2100 | X32: 2400 | Y32: 2600 | Z32: KA０８－２２０７ | AB32: 突出 障子滑車BRT
L33: SLA 80505－DO | N33: 丸ステイ | P33: 2200 | Q33: 2500 | R33: 本 | S33: G S ８０６０５-AO | U33: ガスステイ １５φ | W33: 2500 | X33: 2700 | Y33: 3000 | Z33: KA０８－３５３２ | AB33: ケ－シングBRT | AD33: 700 | AF33: 850
L34: SLA 80505－EO | N34: 丸ステイ | P34: 2300 | Q34: 2600 | R34: 本 | S34: G S ８０６０５-BO | U34: ガスステイ １５φ | W34: 2500 | X34: 2700 | Y34: 3000 | Z34: KA０８－３３１６ | AB34: スペーサー | AD34: 300
L35: SLA 80505－FO | N35: 丸ステイ | P35: 2200 | Q35: 2500 | R35: 本 | S35: G S ８０６０５-CO | U35: ガスステイ １５φ | W35: 2500 | X35: 2800 | Y35: 3000 | Z35: KA８８－２０８ | AD35: 500 | AF35: 600
L36: SLA ８０３０９ | N36: ビスセット | P36: 250 | Q36: 250 | R36: 個 | S36: G S ８０６０５-DO | U36: ガスステイ １５φ | W36: 2600 | X36: 2900 | Y36: 3200 | Z36: KA８８－１３００ | AB36: 中間キャップ | AD36: 300 | AF36: 400
L37: SLA ８２１３１－１０M | N37: コンジット９ | P37: 2500 | Q37: 3000 | R37: 個 | S37: G S ８０６０５-EO | U37: ガスステイ １５φ | W37: 2700 | X37: 3000 | Y37: 3300 | Z37: KA８８－730 | AB37: ケーシングBRT L型 | AD37: 350 | AF37: 450
L38: SLA ８２１３１－２５M | N38: コンジット９ | P38: 6500 | Q38: 7500 | R38: 本 | S38: G S ８０６０５-FO | U38: ガスステイ １５φ | W38: 2800 | X38: 3100 | Y38: 3320 | Z38: KA０８－８０２ R/L | AD38: 600 | AF38: 750
F39: 合計 | I39: =SUM(I21:I26) -> 0 | L39: SLA ８２１３１－５０M | N39: コンジット９ | P39: 12500 | Q39: 14000 | R39: 個 | S39: G S ３５０２５-K１ | U39: ガスステイ ２２φ | W39: 2800 | X39: 3100 | Y39: 3400 | Z39: SLA ８６１０４ | AB39: 障子滑車 | AE39: 650
A40: ～仕様条件～ | L40: SLA ８２０４１ A | N40: ケーシングキャップ | P40: 250 | Q40: 300 | R40: 台 | S40: G S ５００２７-K１ | U40: ガスステイ ２２φ | W40: 2800 | X40: 3100 | Y40: 3400 | Z40: KA ０８－２２０２ | AB40: 障子滑車取付金具 | AE40: 360
A41: 操作ボックス仕様： | L41: SLA ８２０４２ | N41: ９φコンジットクランプ | P41: 50 | Q41: 50 | R41: 本 | S41: G S ２８１２５-１８ | U41: ガスステイ １８φ | W41: 2700 | X41: 3000 | Y41: 3300 | Z41: KA０８－2207 | AB41: スペーサー | AD41: 200 | AE41: 250 | AF41: 300
...

Sheet アイメイ
T2: KA０８ー３３１３ | Z2: 枠滑車取付台座 | AF2: SLA ８０１０６－A | AL2: ステイ用ブラケッN11+AM2:AR89 | AR2: KA０８ー１４１１ | AX2: 枠滑車取付金具 | BD2: MTG－７０R
T4: KA０８ー３３０６ | Z4: スペーサー | AF4: KA０８－４４１ | AL4: ステイ用ブラケット枠 | AR4: KA０８ー１１２１ | AX4: 内倒しブラケット | BD4: MTG－７０R
A6: （ 内 示 注 文 書 ） | T6: KA０８－００２R(L） | Z6: ステイ用ブラケット枠 | AF6: FA０８－０１１－A | AL6: 内倒しブラケット
A8: 特 注 品 見 積 依 頼 兼 回 答 書 | T8: KA０８－５０２R(L） | Z8: ステイ用ブラケット障子 | AF8: SLA １００６１－FE | AL8: 内倒しステイBRT 枠
T10: KA０８－１００９ L | Z10: 内倒しブラケット | AF10: KA０８－１２３（１２２） | AL10: 内倒しステイBRT 障子 | AR10: KA０８－１１１０ | AX10: 内倒しブラケット
K11: 発 行 日 | N11: 令和 8 年 3 月 日
A12: アイメイ株式会社 御中 | T12: KA０８ー１２６ R(L） | Z12: 内倒しステイBRT 障子 | AF12: KA０８－４１０２ R(L） | AL12: 突き出しステイBRT障子 | AR12: KA０８ー１４０４ | AX12: 枠滑車取付金具
T14: KA０８ー５０５ R(L） | Z14: 内倒しステイBRT 枠 | AF14: KA０８－F２５ （１５） | AL14: 突き出しステイBRT枠
J15: 中部システム工業 株式会社
T16: KA０８ー３４０１ | Z16: 突き出し障子滑車BRT | AF16: KA０８－FK－２５ | AL16: 突き出し障子滑車プレート
J17: 〒 ４５4－０９８１
T18: KA０８－３５３２ | Z18: D滑車用ケーシングBRT | AF18: SK３５－A | AL18: 突き出し滑車用スペーサー
A19: 見積依頼 NO | E19: 回答（納期） 日 | J19: 名古屋市中川区吉津１丁目２１０９番地
T20: KA８８ー２２６ R(L） | Z20: 突き出しステイBRT枠 | AF20: KA０８－F ２２ | AL20: 突き出しステイBRT枠
F21: 月 | H21: 日 | J21: アクティブ 名古屋西アントレ E 号
T22: KA８８ー０４２ | Z22: スペーサー | AF22: E/S ０５０－０２０ | AL22: ケーブルロッド | AR22: KA０８ー３３１６ | AX22: スペーサー | BD22: 防火
A23: 工 事 名 | J23: TEL ０５２－４１４－４５８０
T24: KA０８ー７８０１－R/L | Z24: マディオステイBRT 枠 | AF24: SLA ５０００２－００３ | AL24: ナットスペシャル
J25: FAX ０５２－４１４－４５８１
T26: KA０８ー７８０２ | Z26: マディオステイBRT 障子 | AF26: KA ８８－１３００ | AL26: 中間キャップ
A27: 工事番号（発注時） | J27: E-mail s.morimoto@helen.ocn.ne.jp
T28: PRO-SE | AF28: KA ８８－７３０ | AL28: ケーシングブラケット | AR28: 内倒し用
T30: KA０８－５０５ R(L） | Z30: ステイ用ブラケット障子 | AF30: ＫＡ ２５－４０６ | AL30: 内倒ブラケット | AR30: L＝１６０
T32: KA０８－４４１ | Z32: ステイ用ブラケット枠 | AF32: ＫＡ ２５－２０１ | AL32: 内倒本体ブラケット
A33: 品 番 | G33: 品 名 | M33: 色 | O33: 数 量 | Q33: 備 考 | AU33: KA８８－８０２ R(L） | BA33: ステイ用ブラケット障子 外倒し | BG33: フロンテック
T34: KA０８－１１０９ ローラー付 | Z34: 内倒しブラケット | AF34: ＫＡ ２５－１０４ | AL34: コネクター取付金具 | AR34: L
AU35: 特注品 | BA35: ステイ用ブラケット障子 外倒し | BG35: フロンテック
T36: KA０８－１４１ R(L） | Z36: 内倒しステイBRT 障子 | AF36: ＫＡ ２５－００１ | AL36: コネクター取付金具 | AR36: Z
AU37: KA８８－２０８ | BA37: ステイ用ブラケット枠 外倒し | BG37: フロンテック
T38: KA０８－５０５ R(L） | Z38: ステイ用ブラケット枠 | AF38: ＫＡ ２５－４０６－SP | AL38: 内倒ブラケット（特注品）
T40: KA０８－３５６１ R(L） | Z40: C滑車用ケーシングBRT | AF40: E / P -７０ | AL40: 六角軸 L＝７０ | AR40: KA０８ー３３１６ | AX40: スペーサー BFG用
T42: KA０８－４１０５ R(L） | Z42: 突き出しステイBRT障子 | AF42: E / P -１００ | AL42: 六角軸 L＝１００
T44: KA０８－４２６６ | Z44: 突き出しステイBRT枠 | AF44: E / P -５０ 特注 | AL44: 六角軸 L＝５０
AU45: KA０８－４５０２ | BA45: 突き出しステイBRT枠
T46: KA０８－３３０４ | Z46: 枠滑車取付台座 | AF46: KA８８－２７５ | AL46: ステイ用ブラケット
AU47: KA０８－４００１ | BA47: 突き出しステイBRT障子
T48: KA０８－２２０６ | Z48: 障子滑車取付台座 | AF48: KA８８－７２８ R(L） | AL48: ケーシングキャップ取付金具
T50: KA０８－３５７１ R(L） | Z50: 内倒し用ケーシングBRT | AF50: KA ５５－７０５ | AL50: 障子金具
T52: KA８８－７３０ | Z52: ケーシンキャップ取付金具 | AF52: KA ５５－１０９ | AL52: レールユニット取付金具
T54: EXIMA | AF54: SLA ５５２０３－A | AL54: 障子金具 | AR54: 標準A
...

Sheet 豊和発注書
A1: 注 文 書 | O1: N0－１ | Q1: 株式会社 愛知マドコン | V1: 河 田
Q2: 株式会社 豊和 | V2: 知 原
J3: 令和 8 年 3 月 日 | W3: THS １８３０ | Z3: ダンパー
O4: N N ２ ３ R | R4: ハンドルボックス 埋込 | W4: HK １８２０ | Z4: ダンパー
A5: ：：：：：：送信先：：：：：： | O5: N N ２３ | R5: ハンドルボックス 露出 | W5: VB２３－１ | Z5: 皿バネ
J6: 〒４５４－０９８１ | O6: N N ２３ B | R6: ハンドルボックス 露出防錆 | W6: VB２３－２ | Z6: ナット
B7: 株式会社 愛知マドコン | G7: 御 中 | J7: 名古屋市中川区吉津１丁目２１０９番地 | O7: N N ２ ３ RB | R7: ハンドルボックス埋込防錆 | W7: VB２３－３ | Z7: 一般ボルト
E8: 斉藤 | G8: 様 | J8: アクティブ名古屋西アントレ E 号 | O8: H M－３ | R8: ハンドルボックス露出 | W8: VB２３－４ | Z8: 内倒用ボルト
J9: 中部システム工業株式会社 | O9: H M－１ | R9: ハンドルボックス埋込 | W9: AK ８ L－G | Z9: コントロールケーブル
A10: 拝啓 時下ますます御清栄のこととお喜び申し上げます。 | J10: TEL ０５２－４１４－４５８０ | O10: NN２３R－E | R10: 煙感知器連動型ハンドルボックス | W10: WRP－２８ | Z10: 転向滑車
A11: 日頃は、格別のお引き立てを賜り厚く御礼申し上げます。 | J11: FAX ０５２－４１４－４５８１ | O11: mini ３ | R11: ハンドルボックス露出 | W11: WRP－２７ | Z11: コーナー車
A12: 早速ですが下記の通り、注文しますのでご査収下さいま | O12: mini １ | R12: ハンドルボックス埋込 | W12: WRP－７０ | Z12: 大型コーナー車
A13: すようお願い申しあげます。 敬具 | J13: 担当者 ： 一 栁 裕 樹 | O13: F H－２（４） | R13: ハンドルボックス露出 | W13: WR－２６ | Z13: ワイヤー ２mm ５０M
O14: F H－２N（４N） | R14: ハンドルボックス埋込 | W14: WRP－２５ | Z14: ハンドルボックス
A15: 工 事 名 | J15: 納 期 | O15: H M－１E | R15: 煙感知器連動型ハンドルボックス | V15: 28400 | W15: WRP－３１ | Z15: ローラーチェーン
O16: N N３００－３ | R16: ハンドルボックス露出 | W16: ZD－０５－H | Z16: ボックス本体のみ露出
A17: 品 番 | D17: 品 名 | H17: 数量 | I17: 単位 | L17: 備 考 | O17: N N３００－１ | R17: ハンドルボックス埋込 | Z17: ターンバックル（TURN-BC）
O18: N N－２３R | R18: ハンドルボックス埋込 | W18: WC ２８ | Z18: ワイヤースリープ
O19: N N－２３ | R19: ハンドルボックス露出 | W19: WRP ２６－０４ | Z19: 障子ブラケット
R20: 化粧カバー 露出 | W20: WR－２６ | Z20: ワイヤー ２mm １００M
O21: フレンドmini－L | R21: ハンドルボックスSET | V21: 23000 | W21: GH 10-A-S | Z21: ケーブルキヤー本体
R22: 化粧カバー | W22: CH－１１S－５２ | Z22: チェーンケース
R23: ハンドル | W23: CH－１２－９９ | Z23: チェーンケース
O24: N Nー１ | R24: ハンドルボックスSET
O25: N Nー２３－１ | R25: ボックス本体
O26: N Nー２３－２ | R26: 化粧カバー
O27: N Nー２３－３ | R27: 捨箱
O28: N Nー２３－４０ | R28: ハンドル
I35: 計
A36: 送り先
K37: 累計

Sheet メモ書き
